# ffmpeg
Logged in as Yama#5313 (660225799609253905) ------ Ignoring exception in command play: Traceback (most recent call last):   File "/data/user/0/ru.iiec.pydroid3/files/arm-linux-androideabi/lib/python3.8/site-packages/discord/ext/commands/core.py", line 85, in wrapped    ret = await coro(*args, **kwargs)   File "&lt;string>", line 72, in play   File "/data/user/0/ru.iiec.pydroid3/files/arm-linux-androideabi/lib/python3.8/site-packages/discord/player.py", line 225, in __init__     super().__init__(source, executable=executable, args=args, **subprocess_kwargs)   File "/data/user/0/ru.iiec.pydroid3/files/arm-linux-androideabi/lib/python3.8/site-packages/discord/player.py", line 138, in __init__     self._process = self._spawn_process(args, **kwargs)   File "/data/user/0/ru.iiec.pydroid3/files/arm-linux-androideabi/lib/python3.8/site-packages/discord/player.py", line 147, in _spawn_process     raise ClientException(executable + ' was not found.') from None discord.errors.ClientException: ffmpeg was not found.  The above exception was the direct cause of the following exception:  Traceback (most recent call last):   File "/data/user/0/ru.iiec.pydroid3/files/arm-linux-androideabi/lib/python3.8/site-packages/discord/ext/commands/bot.py", line 902, in invoke     await ctx.command.invoke(ctx)   File "/data/user/0/ru.iiec.pydroid3/files/arm-linux-androideabi/lib/python3.8/site-packages/discord/ext/commands/core.py", line 864, in invoke    await injected(*ctx.args, **ctx.kwargs)   File "/data/user/0/ru.iiec.pydroid3/files/arm-linux-androideabi/lib/python3.8/site-packages/discord/ext/commands/core.py", line 94, in wrapped    raise CommandInvokeError(exc) from exc discord.ext.commands.errors.CommandInvokeError: Command raised an exception: ClientException: ffmpeg was not found.
